Workbook

Sheet Para woocommerce
A1: ID | B1: Tipo | C1: SKU | D1: GTIN, UPC, EAN o ISBN | E1: Nombre | F1: Publicado | G1: ¿Está destacado? | H1: Visibilidad en el catálogo | I1: Descripción corta | J1: Descripción | K1: Día en que empieza el precio rebajado | L1: Día en que termina el precio rebajado | M1: Estado del impuesto | N1: Clase de impuesto | O1: ¿Existencias? | P1: Inventario | Q1: Cantidad de bajo inventario | R1: ¿Permitir reservas de productos agotados? | S1: ¿Vendido individualmente? | T1: Peso (kg) | U1: Longitud (cm) | V1: Anchura (cm) | W1: Altura (cm) | X1: ¿Permitir valoraciones de clientes? | Y1: Nota de compra | Z1: Precio rebajado | AA1: Precio normal | AB1: Categorías | AC1: Etiquetas | AD1: Clase de envío | AE1: Imágenes | AF1: Límite de descargas | AG1: Días de caducidad de la descarga | AH1: Superior | AI1: Productos agrupados | AJ1: Ventas dirigidas | AK1: Ventas cruzadas | AL1: URL externa | AM1: Texto del botón | AN1: Posición | AO1: Swatches Attributes | AP1: Marcas | AQ1: Nombre del atributo 1 | AR1: Valor(es) del atributo 1 | AS1: Atributo visible 1 | AT1: Atributo global 1 | AU1: Nombre del atributo 2 | AV1: Valor(es) del atributo 2 | AW1: Atributo visible 2 | AX1: Atributo global 2 | AY1: Nombre del atributo 3 | AZ1: Valor(es) del atributo 3 | BA1: Atributo visible 3 | BB1: Atributo global 3 | BC1: Nombre del atributo 4 | BD1: Valor(es) del atributo 4 | BE1: Atributo visible 4 | BF1: Atributo global 4 | BG1: Nombre del atributo 5 | BH1: Valor(es) del atributo 5 | BI1: Atributo visible 5 | BJ1: Atributo global 5 | BK1: Nombre del atributo 6 | BL1: Valor(es) del atributo 6 | BM1: Atributo visible 6 | BN1: Atributo global 6 | BO1: Nombre del atributo 7 | BP1: Valor(es) del atributo 7 | BQ1: Atributo visible 7 | BR1: Atributo global 7 | BS1: Nombre del atributo 8 | BT1: Valor(es) del atributo 8 | BU1: Atributo visible 8 | BV1: Atributo global 8 | BW1: Nombre del atributo 9 | BX1: Valor(es) del atributo 9 | BY1: Atributo visible 9 | BZ1: Atributo global 9 | CA1: Nombre del atributo 10 | CB1: Valor(es) del atributo 10 | CC1: Atributo visible 10 | CD1: Atributo global 10
A2: =IF(Sistema!A2="","",Sistema!A2) -> 17954 | B2: =IF(Sistema!B2="","",Sistema!B2) -> simple | C2: =IF(Sistema!C2="","",Sistema!C2) -> MKPF02ADA01BR0001 | D2: =IF(Sistema!D2="","",Sistema!D2) | E2: =IF(Sistema!E2="","",Sistema!E2) -> Brakco - Adaptador - Post Mount AP-09 180mm delantero (1 unid) - MKP - Usado, en buen estado | F2: =IF(P2>0,1,IF(Sistema!F2=0,-1,1)) -> 1 | G2: =Sistema!G2 -> 0 | H2: =IF(OR(R2="notify",R2=1),"visible",IF(OR(Sistema!F2=-1,Sistema!F2=0,ISNUMBER(SEARCH("PCK",E2))),"hidden",IF(P2>0,"visible","hidden"))) -> visible | I2: =IF(B2="simple",IF(P2>0,"",IF(R2="notify",Info!C$2,"")),IF(B2="variable",IF(P2>0,"",IF(R2="notify",Info!C$4,"")),"")) | J2: =IF(Sistema!J2="","",Sistema!J2) -> <p>Adaptador Post Mount Brakco AP-09 para montaje de freno delantero con rotor de 180 mm. Fabricado en aluminio para una instalación segura y precisa.</p> | M2: =IF(Sistema!M2="","",Sistema!M2) -> taxable | N2: Estándar | O2: 1 | P2: =Sistema!P2 -> 1 | Q2: =Sistema!Q2 -> 0 | R2: =IF(Sistema!R2=1,"notify",Sistema!R2) -> 0 | T2: =IF(Sistema!T2="","",Sistema!T2) | U2: =IF(Sistema!U2="","",Sistema!U2) | V2: =IF(Sistema!V2="","",Sistema!V2) | W2: =IF(Sistema!W2="","",Sistema!W2) | X2: 1 | Z2: =IF(Sistema!Z2="","",Sistema!Z2) | AA2: =IF(Sistema!AA2="","",Sistema!AA2) -> 20 | AB2: =IF(Sistema!AB2="","",IF(OR(ISNUMBER(SEARCH("MKP",E2)),ISNUMBER(SEARCH("MKP",C2))),"Marketplace > "&Sistema!AB2,Sistema!AB2)) -> Marketplace > Ciclismo > Frenos > Adaptadores para frenos | AC2: =IF(Sistema!AC2="","",Sistema!AC2) | AE2: =IF(Sistema!AE2="","",Sistema!AE2) | AH2: =IF(Sistema!AH2="","",Sistema!AH2) | AQ2: =IF(Sistema!AQ2="","",Sistema!AQ2) | AR2: =IF(Sistema!AR2="","",Sistema!AR2) | AS2: =IF(Sistema!AS2="","",Sistema!AS2) | AT2: =IF(Sistema!AT2="","",Sistema!AT2) | AU2: =IF(Sistema!AU2="","",Sistema!AU2) | AV2: =IF(Sistema!AV2="","",Sistema!AV2) | AW2: =IF(Sistema!AW2="","",Sistema!AW2) | AX2: =IF(Sistema!AX2="","",Sistema!AX2) | ... CD2: =IF(Sistema!CD2="","",Sistema!CD2)
A3: =IF(Sistema!A3="","",Sistema!A3) -> 17969 | B3: =IF(Sistema!B3="","",Sistema!B3) -> simple | C3: =IF(Sistema!C3="","",Sistema!C3) -> MKP978-02-630 | D3: =IF(Sistema!D3="","",Sistema!D3) | E3: =IF(Sistema!E3="","",Sistema!E3) -> FOX - Amortiguador - DHX2 Factory Series 2025-2024, Trunnion, 225x70 mm, 400 lb/in, SLS sin resorte - 978-02-630 - MKP - Usado, en buen estado | F3: =IF(P3>0,1,IF(Sistema!F3=0,-1,1)) -> 1 | G3: =Sistema!G3 -> 0 | H3: =IF(OR(R3="notify",R3=1),"visible",IF(OR(Sistema!F3=-1,Sistema!F3=0,ISNUMBER(SEARCH("PCK",E3))),"hidden",IF(P3>0,"visible","hidden"))) -> visible | I3: =IF(B3="simple",IF(P3>0,"",IF(R3="notify",Info!C$2,"")),IF(B3="variable",IF(P3>0,"",IF(R3="notify",Info!C$4,"")),"")) | J3: =IF(Sistema!J3="","",Sistema!J3) -> <p>Amortiguador trasero FOX DHX2 Factory Series diseñado para bicicletas de descenso y alto rendimiento. Cuenta con ajuste de compresión de alta y baja velocidad (HSC/LSC), rebote de alta y baja velocidad (HSR/LSR), configuración Trunnion y resorte SLS de 400 lb/in. Acabado Matte Stealth con logo a juego.</p><p><strong>Especificaciones:</strong></p><ul><li><p>Modelo: DHX2 Factory Series</p></li><li><p>Años: 2024-2025</p></li><li><p>Configuración: Trunnion</p></li><li><p>Medida: 225 x 70 mm</p></li><li><p>Resorte: SLS 400 lb/in</p></li><li><p>Ajustes: HSC, LSC, HSR, LSR</p></li><li><p>Recubrimiento: Kashima</p></li><li><p>Color: Matte Stealth</p></li><li><p>Aplicación: Mondraker Summum</p></li><li><p>Part Number: 978-02-630</p></li></ul> | M3: =IF(Sistema!M3="","",Sistema!M3) -> taxable | N3: Estándar | O3: 1 | P3: =Sistema!P3 -> 1 | Q3: =Sistema!Q3 -> 0 | R3: =IF(Sistema!R3=1,"notify",Sistema!R3) -> 0 | T3: =IF(Sistema!T3="","",Sistema!T3) | U3: =IF(Sistema!U3="","",Sistema!U3) | V3: =IF(Sistema!V3="","",Sistema!V3) | W3: =IF(Sistema!W3="","",Sistema!W3) | X3: 1 | Z3: =IF(Sistema!Z3="","",Sistema!Z3) | AA3: =IF(Sistema!AA3="","",Sistema!AA3) -> 2310 | AB3: =IF(Sistema!AB3="","",IF(OR(ISNUMBER(SEARCH("MKP",E3)),ISNUMBER(SEARCH("MKP",C3))),"Marketplace > "&Sistema!AB3,Sistema!AB3)) -> Marketplace > Ciclismo > Amortiguador > Shocks | AC3: =IF(Sistema!AC3="","",Sistema!AC3) | AE3: =IF(Sistema!AE3="","",Sistema!AE3) -> https://kuranko.pe/wp-content/uploads/2026/09/WhatsApp-Image-2026-09-19-at-2.31.32-PM.jpeg, https://kuranko.pe/wp-content/uploads/2026/09/WhatsApp-Image-2026-09-19-at-2.31.39-PM.jpeg, https://kuranko.pe/wp-content/uploads/2026/09/WhatsApp-Image-2026-09-19-at-2.31.30-PM.jpeg, https://kuranko.pe/wp-content/uploads/2026/09/WhatsApp-Image-2026-09-19-at-2.31.35-PM.jpeg | AH3: =IF(Sistema!AH3="","",Sistema!AH3) | AQ3: =IF(Sistema!AQ3="","",Sistema!AQ3) | AR3: =IF(Sistema!AR3="","",Sistema!AR3) | AS3: =IF(Sistema!AS3="","",Sistema!AS3) | AT3: =IF(Sistema!AT3="","",Sistema!AT3) | AU3: =IF(Sistema!AU3="","",Sistema!AU3) | AV3: =IF(Sistema!AV3="","",Sistema!AV3) | AW3: =IF(Sistema!AW3="","",Sistema!AW3) | AX3: =IF(Sistema!AX3="","",Sistema!AX3) | ... CD3: =IF(Sistema!CD3="","",Sistema!CD3)
A4: =IF(Sistema!A4="","",Sistema!A4) -> 17970 | B4: =IF(Sistema!B4="","",Sistema!B4) -> simple | C4: =IF(Sistema!C4="","",Sistema!C4) -> MKPR10ROD10GF0004 | D4: =IF(Sistema!D4="","",Sistema!D4) | E4: =IF(Sistema!E4="","",Sistema!E4) -> G Form - Rodillera - Eline - Azul - Talla L- MKP - Usado | F4: =IF(P4>0,1,IF(Sistema!F4=0,-1,1)) -> 1 | G4: =Sistema!G4 -> 0 | H4: =IF(OR(R4="notify",R4=1),"visible",IF(OR(Sistema!F4=-1,Sistema!F4=0,ISNUMBER(SEARCH("PCK",E4))),"hidden",IF(P4>0,"visible","hidden"))) -> visible | I4: =IF(B4="simple",IF(P4>0,"",IF(R4="notify",Info!C$2,"")),IF(B4="variable",IF(P4>0,"",IF(R4="notify",Info!C$4,"")),"")) | J4: =IF(Sistema!J4="","",Sistema!J4) -> <p>Cómodo, protector, ligero y transpirable<br>Los protectores de E-Line están diseñados para jinetes que se enfrentan a paseos agresivos en terrenos técnicos y también quieren permanecer en la silla de montar durante mucho tiempo. Con el énfasis en el ajuste sin igual, la protección al más alto nivel, la comodidad y la transpiración, el E-Line fue desarrollado especialmente para estas necesidades.Características de los protectores de rodilla de E-Line<br>Certificación CE para protectores de motocicletas/bicicletas (CE EN 1621-1:2012), mejor cobertura que la requerida por la certificación CE<br>ventilado, construcción de cuatro capas<br>Espuma EVA para un alto confort de uso<br>almohadillas SmartFlex™</p> | M4: =IF(Sistema!M4="","",Sistema!M4) -> taxable | N4: Estándar | O4: 1 | P4: =Sistema!P4 -> 1 | Q4: =Sistema!Q4 -> 0 | R4: =IF(Sistema!R4=1,"notify",Sistema!R4) -> 0 | T4: =IF(Sistema!T4="","",Sistema!T4) | U4: =IF(Sistema!U4="","",Sistema!U4) | V4: =IF(Sistema!V4="","",Sistema!V4) | W4: =IF(Sistema!W4="","",Sistema!W4) | X4: 1 | Z4: =IF(Sistema!Z4="","",Sistema!Z4) | AA4: =IF(Sistema!AA4="","",Sistema!AA4) -> 300 | AB4: =IF(Sistema!AB4="","",IF(OR(ISNUMBER(SEARCH("MKP",E4)),ISNUMBER(SEARCH("MKP",C4))),"Marketplace > "&Sistema!AB4,Sistema!AB4)) -> Marketplace > Ciclismo > Ropa > Rodilleras | AC4: =IF(Sistema!AC4="","",Sistema!AC4) | AE4: =IF(Sistema!AE4="","",Sistema!AE4) -> https://kuranko.pe/wp-content/uploads/2026/09/WhatsApp-Image-2026-09-19-at-2.34.37-PM-1.jpeg, https://kuranko.pe/wp-content/uploads/2026/09/WhatsApp-Image-2026-09-19-at-2.34.37-PM.jpeg, https://kuranko.pe/wp-content/uploads/2026/09/WhatsApp-Image-2026-09-19-at-2.34.35-PM.jpeg, https://kuranko.pe/wp-content/uploads/2026/09/WhatsApp-Image-2026-09-19-at-2.34.34-PM.jpeg, https://kuranko.pe/wp-content/uploads/2026/09/WhatsApp-Image-2026-09-19-at-2.34.33-PM-1.jpeg, https://kuranko.pe/wp-content/uploads/2026/09/WhatsApp-Image-2026-09-19-at-2.34.33-PM.jpeg, https://kuranko.pe/wp-content/uploads/2026/09/WhatsApp-Image-2026-09-19-at-2.34.31-PM.jpeg | AH4: =IF(Sistema!AH4="","",Sistema!AH4) | AQ4: =IF(Sistema!AQ4="","",Sistema!AQ4) | AR4: =IF(Sistema!AR4="","",Sistema!AR4) | AS4: =IF(Sistema!AS4="","",Sistema!AS4) | AT4: =IF(Sistema!AT4="","",Sistema!AT4) | AU4: =IF(Sistema!AU4="","",Sistema!AU4) | AV4: =IF(Sistema!AV4="","",Sistema!AV4) | AW4: =IF(Sistema!AW4="","",Sistema!AW4) | AX4: =IF(Sistema!AX4="","",Sistema!AX4) | ... CD4: =IF(Sistema!CD4="","",Sistema!CD4)
A5: =IF(Sistema!A5="","",Sistema!A5) -> 17971 | B5: =IF(Sistema!B5="","",Sistema!B5) -> simple | C5: =IF(Sistema!C5="","",Sistema!C5) -> MKPF02ADA01KU0001 | D5: =IF(Sistema!D5="","",Sistema!D5) | E5: =IF(Sistema!E5="","",Sistema!E5) -> Kuranko - Adaptador - Post Mount +20mm (1 unid) - MKP - Usando, en buen estado | F5: =IF(P5>0,1,IF(Sistema!F5=0,-1,1)) -> 1 | G5: =Sistema!G5 -> 0 | H5: =IF(OR(R5="notify",R5=1),"visible",IF(OR(Sistema!F5=-1,Sistema!F5=0,ISNUMBER(SEARCH("PCK",E5))),"hidden",IF(P5>0,"visible","hidden"))) -> visible | I5: =IF(B5="simple",IF(P5>0,"",IF(R5="notify",Info!C$2,"")),IF(B5="variable",IF(P5>0,"",IF(R5="notify",Info!C$4,"")),"")) | J5: =IF(Sistema!J5="","",Sistema!J5) -> <p>Adaptador Post Mount +20 mm fabricado en aluminio, diseñado para aumentar el diámetro del rotor en sistemas de freno compatibles.</p> | M5: =IF(Sistema!M5="","",Sistema!M5) -> taxable | N5: Estándar | O5: 1 | P5: =Sistema!P5 -> 1 | Q5: =Sistema!Q5 -> 0 | R5: =IF(Sistema!R5=1,"notify",Sistema!R5) -> 0 | T5: =IF(Sistema!T5="","",Sistema!T5) | U5: =IF(Sistema!U5="","",Sistema!U5) | V5: =IF(Sistema!V5="","",Sistema!V5) | W5: =IF(Sistema!W5="","",Sistema!W5) | X5: 1 | Z5: =IF(Sistema!Z5="","",Sistema!Z5) | AA5: =IF(Sistema!AA5="","",Sistema!AA5) -> 25 | AB5: =IF(Sistema!AB5="","",IF(OR(ISNUMBER(SEARCH("MKP",E5)),ISNUMBER(SEARCH("MKP",C5))),"Marketplace > "&Sistema!AB5,Sistema!AB5)) -> Marketplace > Ciclismo > Frenos > Adaptadores para frenos | AC5: =IF(Sistema!AC5="","",Sistema!AC5) | AE5: =IF(Sistema!AE5="","",Sistema!AE5) | AH5: =IF(Sistema!AH5="","",Sistema!AH5) | AQ5: =IF(Sistema!AQ5="","",Sistema!AQ5) | AR5: =IF(Sistema!AR5="","",Sistema!AR5) | AS5: =IF(Sistema!AS5="","",Sistema!AS5) | AT5: =IF(Sistema!AT5="","",Sistema!AT5) | AU5: =IF(Sistema!AU5="","",Sistema!AU5) | AV5: =IF(Sistema!AV5="","",Sistema!AV5) | AW5: =IF(Sistema!AW5="","",Sistema!AW5) | AX5: =IF(Sistema!AX5="","",Sistema!AX5) | ... CD5: =IF(Sistema!CD5="","",Sistema!CD5)
A6: =IF(Sistema!A6="","",Sistema!A6) -> 17984 | B6: =IF(Sistema!B6="","",Sistema!B6) -> simple | C6: =IF(Sistema!C6="","",Sistema!C6) -> MKP77651165X | D6: =IF(Sistema!D6="","",Sistema!D6) | E6: =IF(Sistema!E6="","",Sistema!E6) -> Mavic - Kit - de Rueda - 1 Válvula, 2 Radios en J y 2 Nipples MKP | F6: =IF(P6>0,1,IF(Sistema!F6=0,-1,1)) -> 1 | G6: =Sistema!G6 -> 0 | H6: =IF(OR(R6="notify",R6=1),"visible",IF(OR(Sistema!F6=-1,Sistema!F6=0,ISNUMBER(SEARCH("PCK",E6))),"hidden",IF(P6>0,"visible","hidden"))) -> visible | I6: =IF(B6="simple",IF(P6>0,"",IF(R6="notify",Info!C$2,"")),IF(B6="variable",IF(P6>0,"",IF(R6="notify",Info!C$4,"")),"")) | J6: =IF(Sistema!J6="","",Sistema!J6) -> <p>Kit de repuesto Mavic para mantenimiento y reparación de ruedas. Incluye los componentes necesarios para sustituir elementos de la rueda y realizar trabajos de mantenimiento.</p><p><strong>Contenido del kit:</strong></p><ul><li><p>1 válvula</p></li><li><p>2 radios en J</p></li><li><p>2 nipples</p></li></ul> | M6: =IF(Sistema!M6="","",Sistema!M6) -> taxable | N6: Estándar | O6: 1 | P6: =Sistema!P6 -> 2 | Q6: =Sistema!Q6 -> 0 | R6: =IF(Sistema!R6=1,"notify",Sistema!R6) -> 0 | T6: =IF(Sistema!T6="","",Sistema!T6) | U6: =IF(Sistema!U6="","",Sistema!U6) | V6: =IF(Sistema!V6="","",Sistema!V6) | W6: =IF(Sistema!W6="","",Sistema!W6) | X6: 1 | Z6: =IF(Sistema!Z6="","",Sistema!Z6) | AA6: =IF(Sistema!AA6="","",Sistema!AA6) -> 45 | AB6: =IF(Sistema!AB6="","",IF(OR(ISNUMBER(SEARCH("MKP",E6)),ISNUMBER(SEARCH("MKP",C6))),"Marketplace > "&Sistema!AB6,Sistema!AB6)) -> Marketplace > Ciclismo > Ruedas > Repuestos | AC6: =IF(Sistema!AC6="","",Sistema!AC6) | AE6: =IF(Sistema!AE6="","",Sistema!AE6) -> https://kuranko.pe/wp-content/uploads/2026/09/WhatsApp-Image-2026-09-19-at-2.34.30-PM.jpeg, https://kuranko.pe/wp-content/uploads/2026/09/WhatsApp-Image-2026-09-19-at-2.34.29-PM.jpeg, https://kuranko.pe/wp-content/uploads/2026/09/WhatsApp-Image-2026-09-19-at-2.32.02-PM.jpeg | AH6: =IF(Sistema!AH6="","",Sistema!AH6) | AQ6: =IF(Sistema!AQ6="","",Sistema!AQ6) | AR6: =IF(Sistema!AR6="","",Sistema!AR6) | AS6: =IF(Sistema!AS6="","",Sistema!AS6) | AT6: =IF(Sistema!AT6="","",Sistema!AT6) | AU6: =IF(Sistema!AU6="","",Sistema!AU6) | AV6: =IF(Sistema!AV6="","",Sistema!AV6) | AW6: =IF(Sistema!AW6="","",Sistema!AW6) | AX6: =IF(Sistema!AX6="","",Sistema!AX6) | ... CD6: =IF(Sistema!CD6="","",Sistema!CD6)
A7: =IF(Sistema!A7="","",Sistema!A7) -> 17985 | B7: =IF(Sistema!B7="","",Sistema!B7) -> simple | C7: =IF(Sistema!C7="","",Sistema!C7) -> MKPTB00211100 | D7: =IF(Sistema!D7="","",Sistema!D7) | E7: =IF(Sistema!E7="","",Sistema!E7) -> Maxxis - Llanta - Rekon Race 29 x 2.40 EXO/TR 120 TPI, - TB00211100 - MKP - Desmontado, nunca usado | F7: =IF(P7>0,1,IF(Sistema!F7=0,-1,1)) -> 1 | G7: =Sistema!G7 -> 0 | H7: =IF(OR(R7="notify",R7=1),"visible",IF(OR(Sistema!F7=-1,Sistema!F7=0,ISNUMBER(SEARCH("PCK",E7))),"hidden",IF(P7>0,"visible","hidden"))) -> visible | I7: =IF(B7="simple",IF(P7>0,"",IF(R7="notify",Info!C$2,"")),IF(B7="variable",IF(P7>0,"",IF(R7="notify",Info!C$4,"")),"")) | J7: =IF(Sistema!J7="","",Sistema!J7) -> <p>Neumático <strong>Maxxis Rekon Race</strong> de <strong>29 x 2.40</strong>, desarrollado para <strong>XC y competición</strong>, con un diseño de banda de rodadura de bajo perfil que favorece una rodadura rápida en terrenos secos y circuitos de short track.</p><p>Esta versión incorpora carcasa <strong>120 TPI</strong>, protección lateral <strong>EXO</strong>, tecnología <strong>Tubeless Ready</strong> y aro plegable. La medida <strong>29 x 2.40 WT</strong> está optimizada para aros con un ancho interno de <strong>30 mm</strong>.</p><p><strong>Especificaciones:</strong></p><ul><li><p>Marca: <strong>Maxxis</strong></p></li><li><p>Modelo: <strong>Rekon Race</strong></p></li><li><p>Medida: <strong>29 x 2.40 WT</strong></p></li><li><p>ETRTO: <strong>61-622</strong></p></li><li><p>TPI: <strong>120</strong></p></li><li><p>Compuesto: <strong>Dual</strong></p></li><li><p>Carcasa: <strong>EXO</strong></p></li><li><p>Tecnología: <strong>Tubeless Ready (TR)</strong></p></li><li><p>Aro: <strong>Plegable</strong></p></li><li><p>Peso de catálogo: <strong>aprox. 814–816 g</strong></p></li><li><p>Uso recomendado: <strong>XC / XC Race</strong></p></li><li><p>Referencia: <strong>TB00211100</strong></p></li><li><p>Presentación: <strong>1 unidad</strong></p></li></ul> | M7: =IF(Sistema!M7="","",Sistema!M7) -> taxable | N7: Estándar | O7: 1 | P7: =Sistema!P7 -> 1 | Q7: =Sistema!Q7 -> 0 | R7: =IF(Sistema!R7=1,"notify",Sistema!R7) -> 0 | T7: =IF(Sistema!T7="","",Sistema!T7) | U7: =IF(Sistema!U7="","",Sistema!U7) | V7: =IF(Sistema!V7="","",Sistema!V7) | W7: =IF(Sistema!W7="","",Sistema!W7) | X7: 1 | Z7: =IF(Sistema!Z7="","",Sistema!Z7) | AA7: =IF(Sistema!AA7="","",Sistema!AA7) -> 150 | AB7: =IF(Sistema!AB7="","",IF(OR(ISNUMBER(SEARCH("MKP",E7)),ISNUMBER(SEARCH("MKP",C7))),"Marketplace > "&Sistema!AB7,Sistema!AB7)) -> Marketplace > Ciclismo > Ruedas > Cubiertas | AC7: =IF(Sistema!AC7="","",Sistema!AC7) | AE7: =IF(Sistema!AE7="","",Sistema!AE7) -> https://kuranko.pe/wp-content/uploads/2026/09/WhatsApp-Image-2026-09-19-at-2.34.53-PM-3.jpeg, https://kuranko.pe/wp-content/uploads/2026/09/WhatsApp-Image-2026-09-19-at-2.34.53-PM-2.jpeg, https://kuranko.pe/wp-content/uploads/2026/09/WhatsApp-Image-2026-09-19-at-2.34.53-PM-1.jpeg | AH7: =IF(Sistema!AH7="","",Sistema!AH7) | AQ7: =IF(Sistema!AQ7="","",Sistema!AQ7) | AR7: =IF(Sistema!AR7="","",Sistema!AR7) | AS7: =IF(Sistema!AS7="","",Sistema!AS7) | AT7: =IF(Sistema!AT7="","",Sistema!AT7) | AU7: =IF(Sistema!AU7="","",Sistema!AU7) | AV7: =IF(Sistema!AV7="","",Sistema!AV7) | AW7: =IF(Sistema!AW7="","",Sistema!AW7) | AX7: =IF(Sistema!AX7="","",Sistema!AX7) | ... CD7: =IF(Sistema!CD7="","",Sistema!CD7)
A8: =IF(Sistema!A8="","",Sistema!A8) -> 17996 | B8: =IF(Sistema!B8="","",Sistema!B8) -> simple | C8: =IF(Sistema!C8="","",Sistema!C8) -> DY37020.06015MKP | D8: =IF(Sistema!D8="","",Sistema!D8) | E8: =IF(Sistema!E8="","",Sistema!E8) -> ONOFF - Manillar - S6 Carbon 0.2, carbono, 31.8mm, 760mm ancho, 5mm rise, negro - MKP - Desmontado, nunca usado | F8: =IF(P8>0,1,IF(Sistema!F8=0,-1,1)) -> 1 | G8: =Sistema!G8 -> 0 | H8: =IF(OR(R8="notify",R8=1),"visible",IF(OR(Sistema!F8=-1,Sistema!F8=0,ISNUMBER(SEARCH("PCK",E8))),"hidden",IF(P8>0,"visible","hidden"))) -> visible | I8: =IF(B8="simple",IF(P8>0,"",IF(R8="notify",Info!C$2,"")),IF(B8="variable",IF(P8>0,"",IF(R8="notify",Info!C$4,"")),"")) | J8: =IF(Sistema!J8="","",Sistema!J8) -> <p>Manillar de carbono diseñado para XC, down country y trail ligero, ofreciendo una excelente combinación entre bajo peso, rigidez y absorción de vibraciones. Fabricado en fibra de carbono unidireccional, proporciona una conducción precisa y un mayor confort, reduciendo la fatiga en rutas largas y terrenos técnicos.</p><p>Su diámetro de abrazadera de 31.8 mm garantiza compatibilidad con la mayoría de potencias del mercado, mientras que sus 760 mm de ancho y 5 mm de elevación ofrecen un equilibrio ideal entre control, estabilidad y eficiencia de pedaleo. El backsweep de 9° favorece una posición natural de las manos para una mayor comodidad.</p><p>Esta unidad corresponde a una pieza desmontada de bicicleta nueva, nunca utilizada, por lo que se encuentra en excelente estado estético y funcional.</p><p><strong>🛠️ Especificaciones:</strong></p><ul><li><p>Material: Fibra de carbono unidireccional</p></li><li><p>Diámetro de abrazadera: 31.8 mm</p></li><li><p>Ancho: 760 mm</p></li><li><p>Elevación (Rise): 5 mm</p></li><li><p>Backsweep: 9°</p></li><li><p>Upsweep: 0°</p></li><li><p>Color: Negro</p></li><li><p>Uso recomendado: XC / Down Country / Trail ligero</p></li><li><p>Estado: Desmontado, nunca usado</p></li></ul> | M8: =IF(Sistema!M8="","",Sistema!M8) -> taxable | N8: Estándar | O8: 1 | P8: =Sistema!P8 -> 1 | Q8: =Sistema!Q8 -> 0 | R8: =IF(Sistema!R8=1,"notify",Sistema!R8) -> 0 | T8: =IF(Sistema!T8="","",Sistema!T8) | U8: =IF(Sistema!U8="","",Sistema!U8) | V8: =IF(Sistema!V8="","",Sistema!V8) | W8: =IF(Sistema!W8="","",Sistema!W8) | X8: 1 | Z8: =IF(Sistema!Z8="","",Sistema!Z8) | AA8: =IF(Sistema!AA8="","",Sistema!AA8) -> 680 | AB8: =IF(Sistema!AB8="","",IF(OR(ISNUMBER(SEARCH("MKP",E8)),ISNUMBER(SEARCH("MKP",C8))),"Marketplace > "&Sistema!AB8,Sistema!AB8)) -> Marketplace > Ciclismo > Dirección > Manillares | AC8: =IF(Sistema!AC8="","",Sistema!AC8) | AE8: =IF(Sistema!AE8="","",Sistema!AE8) -> https://kuranko.pe/wp-content/uploads/2026/09/WhatsApp-Image-2026-09-19-at-2.34.52-PM-1.jpeg, https://kuranko.pe/wp-content/uploads/2026/09/WhatsApp-Image-2026-09-19-at-2.34.52-PM-2.jpeg, https://kuranko.pe/wp-content/uploads/2026/09/WhatsApp-Image-2026-09-19-at-2.34.51-PM.jpeg, https://kuranko.pe/wp-content/uploads/2026/09/WhatsApp-Image-2026-09-19-at-2.34.50-PM-1.jpeg, https://kuranko.pe/wp-content/uploads/2026/09/WhatsApp-Image-2026-09-19-at-2.34.50-PM.jpeg, https://kuranko.pe/wp-content/uploads/2026/09/WhatsApp-Image-2026-09-19-at-2.34.49-PM-1.jpeg | AH8: =IF(Sistema!AH8="","",Sistema!AH8) | AQ8: =IF(Sistema!AQ8="","",Sistema!AQ8) | AR8: =IF(Sistema!AR8="","",Sistema!AR8) | AS8: =IF(Sistema!AS8="","",Sistema!AS8) | AT8: =IF(Sistema!AT8="","",Sistema!AT8) | AU8: =IF(Sistema!AU8="","",Sistema!AU8) | AV8: =IF(Sistema!AV8="","",Sistema!AV8) | AW8: =IF(Sistema!AW8="","",Sistema!AW8) | AX8: =IF(Sistema!AX8="","",Sistema!AX8) | ... CD8: =IF(Sistema!CD8="","",Sistema!CD8)
A9: =IF(Sistema!A9="","",Sistema!A9) -> 18009 | B9: =IF(Sistema!B9="","",Sistema!B9) -> simple | C9: =IF(Sistema!C9="","",Sistema!C9) -> MKP00.4020.572.005 | D9: =IF(Sistema!D9="","",Sistema!D9) | E9: =IF(Sistema!E9="","",Sistema!E9) -> RockShox - Vástago - de aire - DebonAir C1 130 mm para Lyrik/Yari A1+ (2016+) - MKP - Usado, en buen estado | F9: =IF(P9>0,1,IF(Sistema!F9=0,-1,1)) -> 1 | G9: =Sistema!G9 -> 0 | H9: =IF(OR(R9="notify",R9=1),"visible",IF(OR(Sistema!F9=-1,Sistema!F9=0,ISNUMBER(SEARCH("PCK",E9))),"hidden",IF(P9>0,"visible","hidden"))) -> visible | I9: =IF(B9="simple",IF(P9>0,"",IF(R9="notify",Info!C$2,"")),IF(B9="variable",IF(P9>0,"",IF(R9="notify",Info!C$4,"")),"")) | J9: =IF(Sistema!J9="","",Sistema!J9) -> <p>Vástago de aire DebonAir C1 de 130 mm para horquillas RockShox Lyrik y Yari compatibles. Permite configurar la horquilla para un recorrido de 130 mm mediante el sistema de aire DebonAir C1.</p><p><strong>Compatibilidad:</strong></p><ul><li><p>RockShox Lyrik A1-C3, 2016-2022</p></li><li><p>RockShox Yari A1-B3, 2016-2022</p></li></ul><p><strong>Especificaciones:</strong></p><ul><li><p>Sistema: DebonAir C1</p></li><li><p>Recorrido: 130 mm</p></li><li><p>Tipo: Vástago de aire / Air Shaft</p></li></ul> | M9: =IF(Sistema!M9="","",Sistema!M9) -> taxable | N9: Estándar | O9: 1 | P9: =Sistema!P9 -> 1 | Q9: =Sistema!Q9 -> 0 | R9: =IF(Sistema!R9=1,"notify",Sistema!R9) -> 0 | T9: =IF(Sistema!T9="","",Sistema!T9) | U9: =IF(Sistema!U9="","",Sistema!U9) | V9: =IF(Sistema!V9="","",Sistema!V9) | W9: =IF(Sistema!W9="","",Sistema!W9) | X9: 1 | Z9: =IF(Sistema!Z9="","",Sistema!Z9) | AA9: =IF(Sistema!AA9="","",Sistema!AA9) -> 200 | AB9: =IF(Sistema!AB9="","",IF(OR(ISNUMBER(SEARCH("MKP",E9)),ISNUMBER(SEARCH("MKP",C9))),"Marketplace > "&Sistema!AB9,Sistema!AB9)) -> Marketplace > Ciclismo > Amortiguador > Muelles para horquillas | AC9: =IF(Sistema!AC9="","",Sistema!AC9) | AE9: =IF(Sistema!AE9="","",Sistema!AE9) -> https://kuranko.pe/wp-content/uploads/2026/09/WhatsApp-Image-2026-09-19-at-2.31.29-PM.jpeg, https://kuranko.pe/wp-content/uploads/2026/09/WhatsApp-Image-2026-09-19-at-2.31.28-PM.jpeg | AH9: =IF(Sistema!AH9="","",Sistema!AH9) | AQ9: =IF(Sistema!AQ9="","",Sistema!AQ9) | AR9: =IF(Sistema!AR9="","",Sistema!AR9) | AS9: =IF(Sistema!AS9="","",Sistema!AS9) | AT9: =IF(Sistema!AT9="","",Sistema!AT9) | AU9: =IF(Sistema!AU9="","",Sistema!AU9) | AV9: =IF(Sistema!AV9="","",Sistema!AV9) | AW9: =IF(Sistema!AW9="","",Sistema!AW9) | AX9: =IF(Sistema!AX9="","",Sistema!AX9) | ... CD9: =IF(Sistema!CD9="","",Sistema!CD9)
A10: =IF(Sistema!A10="","",Sistema!A10) -> 18023 | B10: =IF(Sistema!B10="","",Sistema!B10) -> simple | C10: =IF(Sistema!C10="","",Sistema!C10) -> PRD-000009 | D10: =IF(Sistema!D10="","",Sistema!D10) | E10: =IF(Sistema!E10="","",Sistema!E10) -> Shimano - Descarrilador - SLX M7100 Shadow+ SGS Black 12s / Max 51t - MKP - Usado | F10: =IF(P10>0,1,IF(Sistema!F10=0,-1,1)) -> 1 | G10: =Sistema!G10 -> 0 | H10: =IF(OR(R10="notify",R10=1),"visible",IF(OR(Sistema!F10=-1,Sistema!F10=0,ISNUMBER(SEARCH("PCK",E10))),"hidden",IF(P10>0,"visible","hidden"))) -> visible | I10: =IF(B10="simple",IF(P10>0,"",IF(R10="notify",Info!C$2,"")),IF(B10="variable",IF(P10>0,"",IF(R10="notify",Info!C$4,"")),"")) | J10: =IF(Sistema!J10="","",Sistema!J10) -> <p></p> | M10: =IF(Sistema!M10="","",Sistema!M10) -> taxable | N10: Estándar | O10: 1 | P10: =Sistema!P10 -> 1 | Q10: =Sistema!Q10 -> 0 | R10: =IF(Sistema!R10=1,"notify",Sistema!R10) -> 0 | T10: =IF(Sistema!T10="","",Sistema!T10) | U10: =IF(Sistema!U10="","",Sistema!U10) | V10: =IF(Sistema!V10="","",Sistema!V10) | W10: =IF(Sistema!W10="","",Sistema!W10) | X10: 1 | Z10: =IF(Sistema!Z10="","",Sistema!Z10) | AA10: =IF(Sistema!AA10="","",Sistema!AA10) -> 250 | AB10: =IF(Sistema!AB10="","",IF(OR(ISNUMBER(SEARCH("MKP",E10)),ISNUMBER(SEARCH("MKP",C10))),"Marketplace > "&Sistema!AB10,Sistema!AB10)) -> Marketplace > Ciclismo > Transmisión > Descarrilador | AC10: =IF(Sistema!AC10="","",Sistema!AC10) | AE10: =IF(Sistema!AE10="","",Sistema!AE10) -> https://kuranko.pe/wp-content/uploads/2026/07/WhatsApp-Image-2026-07-24-at-7.19.49-PM.jpeg, https://kuranko.pe/wp-content/uploads/2026/07/WhatsApp-Image-2026-07-24-at-7.19.48-PM-1.jpeg | AH10: =IF(Sistema!AH10="","",Sistema!AH10) | AQ10: =IF(Sistema!AQ10="","",Sistema!AQ10) | AR10: =IF(Sistema!AR10="","",Sistema!AR10) | AS10: =IF(Sistema!AS10="","",Sistema!AS10) | AT10: =IF(Sistema!AT10="","",Sistema!AT10) | AU10: =IF(Sistema!AU10="","",Sistema!AU10) | AV10: =IF(Sistema!AV10="","",Sistema!AV10) | AW10: =IF(Sistema!AW10="","",Sistema!AW10) | AX10: =IF(Sistema!AX10="","",Sistema!AX10) | ... CD10: =IF(Sistema!CD10="","",Sistema!CD10)
A11: =IF(Sistema!A11="","",Sistema!A11) -> 18024 | B11: =IF(Sistema!B11="","",Sistema!B11) -> simple | C11: =IF(Sistema!C11="","",Sistema!C11) -> MKP4550170451967 | D11: =IF(Sistema!D11="","",Sistema!D11) | E11: =IF(Sistema!E11="","",Sistema!E11) -> Shimano - Disco - SLX SM-RT64 Center Lock 180mm - MKP - Usado, en buen estado | F11: =IF(P11>0,1,IF(Sistema!F11=0,-1,1)) -> 1 | G11: =Sistema!G11 -> 0 | H11: =IF(OR(R11="notify",R11=1),"visible",IF(OR(Sistema!F11=-1,Sistema!F11=0,ISNUMBER(SEARCH("PCK",E11))),"hidden",IF(P11>0,"visible","hidden"))) -> visible | I11: =IF(B11="simple",IF(P11>0,"",IF(R11="notify",Info!C$2,"")),IF(B11="variable",IF(P11>0,"",IF(R11="notify",Info!C$4,"")),"")) | J11: =IF(Sistema!J11="","",Sistema!J11) -> <p>Disco Shimano SLX SM-RT64 Center LockLa superficie de frenada en acero inoxidable cortada con precisión garantiza la limpieza de la pastilla en condiciones de barro y ayuda al enfriamiento bajo esfuerzos elevados.<br>Se incrementa la durabilidad y las prestaciones de la pastilla de freno<br>La araña en aleación de aluminio hace de soporte a la superficie del rotor, aumentando la rigidez y reduciendo el peso.Peso: alrededor de 153 g. (160 mm)<br>12 g más ligero que el SM-RT62.</p> | M11: =IF(Sistema!M11="","",Sistema!M11) -> taxable | N11: Estándar | O11: 1 | P11: =Sistema!P11 -> 1 | Q11: =Sistema!Q11 -> 0 | R11: =IF(Sistema!R11=1,"notify",Sistema!R11) -> 0 | T11: =IF(Sistema!T11="","",Sistema!T11) | U11: =IF(Sistema!U11="","",Sistema!U11) | V11: =IF(Sistema!V11="","",Sistema!V11) | W11: =IF(Sistema!W11="","",Sistema!W11) | X11: 1 | Z11: =IF(Sistema!Z11="","",Sistema!Z11) | AA11: =IF(Sistema!AA11="","",Sistema!AA11) | AB11: =IF(Sistema!AB11="","",IF(OR(ISNUMBER(SEARCH("MKP",E11)),ISNUMBER(SEARCH("MKP",C11))),"Marketplace > "&Sistema!AB11,Sistema!AB11)) -> Marketplace > Ciclismo > Frenos > Discos para frenos | AC11: =IF(Sistema!AC11="","",Sistema!AC11) | AE11: =IF(Sistema!AE11="","",Sistema!AE11) -> https://kuranko.pe/wp-content/uploads/2026/09/WhatsApp-Image-2026-09-19-at-2.31.54-PM.jpeg, https://kuranko.pe/wp-content/uploads/2026/09/WhatsApp-Image-2026-09-19-at-2.31.49-PM.jpeg, https://kuranko.pe/wp-content/uploads/2026/09/WhatsApp-Image-2026-09-19-at-2.31.47-PM.jpeg, https://kuranko.pe/wp-content/uploads/2026/09/WhatsApp-Image-2026-09-19-at-2.31.45-PM.jpeg, https://kuranko.pe/wp-content/uploads/2026/09/WhatsApp-Image-2026-09-19-at-2.31.43-PM.jpeg | AH11: =IF(Sistema!AH11="","",Sistema!AH11) | AQ11: =IF(Sistema!AQ11="","",Sistema!AQ11) | AR11: =IF(Sistema!AR11="","",Sistema!AR11) | AS11: =IF(Sistema!AS11="","",Sistema!AS11) | AT11: =IF(Sistema!AT11="","",Sistema!AT11) | AU11: =IF(Sistema!AU11="","",Sistema!AU11) | AV11: =IF(Sistema!AV11="","",Sistema!AV11) | AW11: =IF(Sistema!AW11="","",Sistema!AW11) | AX11: =IF(Sistema!AX11="","",Sistema!AX11) | ... CD11: =IF(Sistema!CD11="","",Sistema!CD11)
A12: =IF(Sistema!A12="","",Sistema!A12) -> 18025 | B12: =IF(Sistema!B12="","",Sistema!B12) -> simple | C12: =IF(Sistema!C12="","",Sistema!C12) -> MKP0000000036 | D12: =IF(Sistema!D12="","",Sistema!D12) | E12: =IF(Sistema!E12="","",Sistema!E12) -> Shimano - Freno - delantero Deore XT M8100, sin pastillas - MKP - Usado, en buen estado | F12: =IF(P12>0,1,IF(Sistema!F12=0,-1,1)) -> 1 | G12: =Sistema!G12 -> 0 | H12: =IF(OR(R12="notify",R12=1),"visible",IF(OR(Sistema!F12=-1,Sistema!F12=0,ISNUMBER(SEARCH("PCK",E12))),"hidden",IF(P12>0,"visible","hidden"))) -> visible | I12: =IF(B12="simple",IF(P12>0,"",IF(R12="notify",Info!C$2,"")),IF(B12="variable",IF(P12>0,"",IF(R12="notify",Info!C$4,"")),"")) | J12: =IF(Sistema!J12="","",Sistema!J12) -> Freno hidráulico de alto rendimiento diseñado para MTB XC, trail y enduro ligero, ofreciendo excelente potencia, modulación y control en todo tipo de terrenos. La serie Deore XT M8100 destaca por su tacto preciso y respuesta consistente, ideal para ciclistas que buscan rendimiento confiable tanto en rutas técnicas como en largas jornadas de montaña. La construcción ligera y resistente mejora la disipación de calor y mantiene un funcionamiento estable incluso en descensos exigentes. Esta unidad corresponde a una pieza MKP desmontada, usada y en buen estado funcional y estético. Se entrega sin pastillas de freno. 🛠️ Especificaciones: Posición: Delantero Serie: Shimano Deore XT M8100 Tipo: Freno hidráulico de disco Color: Negro Incluye maneta y caliper No incluye pastillas Estado: MKP – usado, en buen estado | M12: =IF(Sistema!M12="","",Sistema!M12) -> taxable | N12: Estándar | O12: 1 | P12: =Sistema!P12 -> 1 | Q12: =Sistema!Q12 -> 0 | R12: =IF(Sistema!R12=1,"notify",Sistema!R12) -> 0 | T12: =IF(Sistema!T12="","",Sistema!T12) | U12: =IF(Sistema!U12="","",Sistema!U12) | V12: =IF(Sistema!V12="","",Sistema!V12) | W12: =IF(Sistema!W12="","",Sistema!W12) | X12: 1 | Z12: =IF(Sistema!Z12="","",Sistema!Z12) -> 300 | AA12: =IF(Sistema!AA12="","",Sistema!AA12) -> 300 | AB12: =IF(Sistema!AB12="","",IF(OR(ISNUMBER(SEARCH("MKP",E12)),ISNUMBER(SEARCH("MKP",C12))),"Marketplace > "&Sistema!AB12,Sistema!AB12)) -> Marketplace > Ciclismo > Frenos > Frenos de disco y aro | AC12: =IF(Sistema!AC12="","",Sistema!AC12) | AE12: =IF(Sistema!AE12="","",Sistema!AE12) -> https://kuranko.pe/wp-content/uploads/2026/07/WhatsApp-Image-2026-07-22-at-4.51.42-PM.jpeg, https://kuranko.pe/wp-content/uploads/2026/07/WhatsApp-Image-2026-07-22-at-4.51.41-PM-1.jpeg, https://kuranko.pe/wp-content/uploads/2026/07/WhatsApp-Image-2026-07-22-at-4.51.41-PM.jpeg, https://kuranko.pe/wp-content/uploads/2026/07/WhatsApp-Image-2026-07-22-at-4.51.40-PM-2.jpeg, https://kuranko.pe/wp-content/uploads/2026/07/WhatsApp-Image-2026-07-22-at-4.51.40-PM-1.jpeg, https://kuranko.pe/wp-content/uploads/2026/07/WhatsApp-Image-2026-07-22-at-4.51.40-PM.jpeg, https://kuranko.pe/wp-content/uploads/2026/07/WhatsApp-Image-2026-07-22-at-4.51.39-PM-1.jpeg | AH12: =IF(Sistema!AH12="","",Sistema!AH12) | AQ12: =IF(Sistema!AQ12="","",Sistema!AQ12) | AR12: =IF(Sistema!AR12="","",Sistema!AR12) | AS12: =IF(Sistema!AS12="","",Sistema!AS12) | AT12: =IF(Sistema!AT12="","",Sistema!AT12) | AU12: =IF(Sistema!AU12="","",Sistema!AU12) | AV12: =IF(Sistema!AV12="","",Sistema!AV12) | AW12: =IF(Sistema!AW12="","",Sistema!AW12) | AX12: =IF(Sistema!AX12="","",Sistema!AX12) | ... CD12: =IF(Sistema!CD12="","",Sistema!CD12)
A13: =IF(Sistema!A13="","",Sistema!A13) -> 18026 | B13: =IF(Sistema!B13="","",Sistema!B13) -> simple | C13: =IF(Sistema!C13="","",Sistema!C13) -> MKP0000000051 | D13: =IF(Sistema!D13="","",Sistema!D13) | E13: =IF(Sistema!E13="","",Sistema!E13) -> Shimano - Frenos - Deore xt 4 pistones usados MKP | F13: =IF(P13>0,1,IF(Sistema!F13=0,-1,1)) -> 1 | G13: =Sistema!G13 -> 0 | H13: =IF(OR(R13="notify",R13=1),"visible",IF(OR(Sistema!F13=-1,Sistema!F13=0,ISNUMBER(SEARCH("PCK",E13))),"hidden",IF(P13>0,"visible","hidden"))) -> hidden | I13: =IF(B13="simple",IF(P13>0,"",IF(R13="notify",Info!C$2,"")),IF(B13="variable",IF(P13>0,"",IF(R13="notify",Info!C$4,"")),"")) | J13: =IF(Sistema!J13="","",Sistema!J13) | M13: =IF(Sistema!M13="","",Sistema!M13) -> taxable | N13: Estándar | O13: 1 | P13: =Sistema!P13 -> 0 | Q13: =Sistema!Q13 -> 0 | R13: =IF(Sistema!R13=1,"notify",Sistema!R13) -> 0 | T13: =IF(Sistema!T13="","",Sistema!T13) | U13: =IF(Sistema!U13="","",Sistema!U13) | V13: =IF(Sistema!V13="","",Sistema!V13) | W13: =IF(Sistema!W13="","",Sistema!W13) | X13: 1 | Z13: =IF(Sistema!Z13="","",Sistema!Z13) | AA13: =IF(Sistema!AA13="","",Sistema!AA13) | AB13: =IF(Sistema!AB13="","",IF(OR(ISNUMBER(SEARCH("MKP",E13)),ISNUMBER(SEARCH("MKP",C13))),"Marketplace > "&Sistema!AB13,Sistema!AB13)) -> Marketplace > Ciclismo > Frenos > Frenos de disco y aro | AC13: =IF(Sistema!AC13="","",Sistema!AC13) | AE13: =IF(Sistema!AE13="","",Sistema!AE13) | AH13: =IF(Sistema!AH13="","",Sistema!AH13) | AQ13: =IF(Sistema!AQ13="","",Sistema!AQ13) | AR13: =IF(Sistema!AR13="","",Sistema!AR13) | AS13: =IF(Sistema!AS13="","",Sistema!AS13) | AT13: =IF(Sistema!AT13="","",Sistema!AT13) | AU13: =IF(Sistema!AU13="","",Sistema!AU13) | AV13: =IF(Sistema!AV13="","",Sistema!AV13) | AW13: =IF(Sistema!AW13="","",Sistema!AW13) | AX13: =IF(Sistema!AX13="","",Sistema!AX13) | ... CD13: =IF(Sistema!CD13="","",Sistema!CD13)
... A303: =IF(Sistema!A303="","",Sistema!A303) | B303: =IF(Sistema!B303="","",Sistema!B303) | C303: =IF(Sistema!C303="","",Sistema!C303) | D303: =IF(Sistema!D303="","",Sistema!D303) | E303: =IF(Sistema!E303="","",Sistema!E303) | F303: =IF(P303>0,1,IF(Sistema!F303=0,-1,1)) -> -1 | G303: =Sistema!G303 -> 0 | H303: =IF(OR(R303="notify",R303=1),"visible",IF(OR(Sistema!F303=-1,Sistema!F303=0,ISNUMBER(SEARCH("PCK",E303))),"hidden",IF(P303>0,"visible","hidden"))) -> hidden | I303: =IF(B303="simple",IF(P303>0,"",IF(R303="notify",Info!C$2,"")),IF(B303="variable",IF(P303>0,"",IF(R303="notify",Info!C$4,"")),"")) | J303: =IF(Sistema!J303="","",Sistema!J303) | M303: =IF(Sistema!M303="","",Sistema!M303) | N303: Estándar | O303: 1 | P303: =Sistema!P303 -> 0 | Q303: =Sistema!Q303 -> 0 | R303: =IF(Sistema!R303=1,"notify",Sistema!R303) -> 0 | T303: =IF(Sistema!T303="","",Sistema!T303) | U303: =IF(Sistema!U303="","",Sistema!U303) | V303: =IF(Sistema!V303="","",Sistema!V303) | W303: =IF(Sistema!W303="","",Sistema!W303) | X303: 1 | Z303: =IF(Sistema!Z303="","",Sistema!Z303) | AA303: =IF(Sistema!AA303="","",Sistema!AA303) | AB303: =IF(Sistema!AB303="","",IF(OR(ISNUMBER(SEARCH("MKP",E303)),ISNUMBER(SEARCH("MKP",C303))),"Marketplace > "&Sistema!AB303,Sistema!AB303)) | AC303: =IF(Sistema!AC303="","",Sistema!AC303) | AE303: =IF(Sistema!AE303="","",Sistema!AE303) | AH303: =IF(Sistema!AH303="","",Sistema!AH303) | AQ303: =IF(Sistema!AQ303="","",Sistema!AQ303) | AR303: =IF(Sistema!AR303="","",Sistema!AR303) | AS303: =IF(Sistema!AS303="","",Sistema!AS303) | AT303: =IF(Sistema!AT303="","",Sistema!AT303) | AU303: =IF(Sistema!AU303="","",Sistema!AU303) | AV303: =IF(Sistema!AV303="","",Sistema!AV303) | AW303: =IF(Sistema!AW303="","",Sistema!AW303) | AX303: =IF(Sistema!AX303="","",Sistema!AX303) | ... CD303: =IF(Sistema!CD303="","",Sistema!CD303)

Sheet Sistema
A1: ID | B1: Tipo | C1: SKU | D1: GTIN, UPC, EAN o ISBN | E1: Nombre | F1: Publicado | G1: ¿Está destacado? | H1: Visibilidad en el catálogo | I1: Descripción corta | J1: Descripción | K1: Día en que empieza el precio rebajado | L1: Día en que termina el precio rebajado | M1: Estado del impuesto | N1: Clase de impuesto | O1: ¿Existencias? | P1: Inventario | Q1: Cantidad de bajo inventario | R1: ¿Permitir reservas de productos agotados? | S1: ¿Vendido individualmente? | T1: Peso (kg) | U1: Longitud (cm) | V1: Anchura (cm) | W1: Altura (cm) | X1: ¿Permitir valoraciones de clientes? | Y1: Nota de compra | Z1: Precio rebajado | AA1: Precio normal | AB1: Categorías | AC1: Etiquetas | AD1: Clase de envío | AE1: Imágenes | AF1: Límite de descargas | AG1: Días de caducidad de la descarga | AH1: Superior | AI1: Productos agrupados | AJ1: Ventas dirigidas | AK1: Ventas cruzadas | AL1: URL externa | AM1: Texto del botón | AN1: Posición | AO1: Swatches Attributes | AP1: Marcas | AQ1: Nombre del atributo 1 | AR1: Valor(es) del atributo 1 | AS1: Atributo visible 1 | AT1: Atributo global 1 | AU1: Nombre del atributo 2 | AV1: Valor(es) del atributo 2 | AW1: Atributo visible 2 | AX1: Atributo global 2 | AY1: Nombre del atributo 3 | AZ1: Valor(es) del atributo 3 | BA1: Atributo visible 3 | BB1: Atributo global 3 | BC1: Nombre del atributo 4 | BD1: Valor(es) del atributo 4 | BE1: Atributo visible 4 | BF1: Atributo global 4 | BG1: Nombre del atributo 5 | BH1: Valor(es) del atributo 5 | BI1: Atributo visible 5 | BJ1: Atributo global 5 | BK1: Nombre del atributo 6 | BL1: Valor(es) del atributo 6 | BM1: Atributo visible 6 | BN1: Atributo global 6 | BO1: Nombre del atributo 7 | BP1: Valor(es) del atributo 7 | BQ1: Atributo visible 7 | BR1: Atributo global 7 | BS1: Nombre del atributo 8 | BT1: Valor(es) del atributo 8 | BU1: Atributo visible 8 | BV1: Atributo global 8 | BW1: Nombre del atributo 9 | BX1: Valor(es) del atributo 9 | BY1: Atributo visible 9 | BZ1: Atributo global 9 | CA1: Nombre del atributo 10 | CB1: Valor(es) del atributo 10 | CC1: Atributo visible 10 | CD1: Atributo global 10
A2: 17954 | B2: simple | C2: MKPF02ADA01BR0001 | E2: Brakco - Adaptador - Post Mount AP-09 180mm delantero (1 unid) - MKP - Usado, en buen estado | F2: 1 | G2: 0 | H2: visible | J2: <p>Adaptador Post Mount Brakco AP-09 para montaje de freno delantero con rotor de 180 mm. Fabricado en aluminio para una instalación segura y precisa.</p> | M2: taxable | O2: 1 | P2: 1 | S2: 0 | AA2: 20 | AB2: Ciclismo > Frenos > Adaptadores para frenos
A3: 17969 | B3: simple | C3: MKP978-02-630 | E3: FOX - Amortiguador - DHX2 Factory Series 2025-2024, Trunnion, 225x70 mm, 400 lb/in, SLS sin resorte - 978-02-630 - MKP - Usado, en buen estado | F3: 1 | G3: 0 | H3: visible | J3: <p>Amortiguador trasero FOX DHX2 Factory Series diseñado para bicicletas de descenso y alto rendimiento. Cuenta con ajuste de compresión de alta y baja velocidad (HSC/LSC), rebote de alta y baja velocidad (HSR/LSR), configuración Trunnion y resorte SLS de 400 lb/in. Acabado Matte Stealth con logo a juego.</p><p><strong>Especificaciones:</strong></p><ul><li><p>Modelo: DHX2 Factory Series</p></li><li><p>Años: 2024-2025</p></li><li><p>Configuración: Trunnion</p></li><li><p>Medida: 225 x 70 mm</p></li><li><p>Resorte: SLS 400 lb/in</p></li><li><p>Ajustes: HSC, LSC, HSR, LSR</p></li><li><p>Recubrimiento: Kashima</p></li><li><p>Color: Matte Stealth</p></li><li><p>Aplicación: Mondraker Summum</p></li><li><p>Part Number: 978-02-630</p></li></ul> | M3: taxable | O3: 1 | P3: 1 | S3: 0 | AA3: 2310 | AB3: Ciclismo > Amortiguador > Shocks | AE3: https://kuranko.pe/wp-content/uploads/2026/09/WhatsApp-Image-2026-09-19-at-2.31.32-PM.jpeg, https://kuranko.pe/wp-content/uploads/2026/09/WhatsApp-Image-2026-09-19-at-2.31.39-PM.jpeg, https://kuranko.pe/wp-content/uploads/2026/09/WhatsApp-Image-2026-09-19-at-2.31.30-PM.jpeg, https://kuranko.pe/wp-content/uploads/2026/09/WhatsApp-Image-2026-09-19-at-2.31.35-PM.jpeg
A4: 17970 | B4: simple | C4: MKPR10ROD10GF0004 | E4: G Form - Rodillera - Eline - Azul - Talla L- MKP - Usado | F4: 1 | G4: 0 | H4: visible | J4: <p>Cómodo, protector, ligero y transpirable<br>Los protectores de E-Line están diseñados para jinetes que se enfrentan a paseos agresivos en terrenos técnicos y también quieren permanecer en la silla de montar durante mucho tiempo. Con el énfasis en el ajuste sin igual, la protección al más alto nivel, la comodidad y la transpiración, el E-Line fue desarrollado especialmente para estas necesidades.Características de los protectores de rodilla de E-Line<br>Certificación CE para protectores de motocicletas/bicicletas (CE EN 1621-1:2012), mejor cobertura que la requerida por la certificación CE<br>ventilado, construcción de cuatro capas<br>Espuma EVA para un alto confort de uso<br>almohadillas SmartFlex™</p> | M4: taxable | O4: 1 | P4: 1 | S4: 0 | AA4: 300 | AB4: Ciclismo > Ropa > Rodilleras | AE4: https://kuranko.pe/wp-content/uploads/2026/09/WhatsApp-Image-2026-09-19-at-2.34.37-PM-1.jpeg, https://kuranko.pe/wp-content/uploads/2026/09/WhatsApp-Image-2026-09-19-at-2.34.37-PM.jpeg, https://kuranko.pe/wp-content/uploads/2026/09/WhatsApp-Image-2026-09-19-at-2.34.35-PM.jpeg, https://kuranko.pe/wp-content/uploads/2026/09/WhatsApp-Image-2026-09-19-at-2.34.34-PM.jpeg, https://kuranko.pe/wp-content/uploads/2026/09/WhatsApp-Image-2026-09-19-at-2.34.33-PM-1.jpeg, https://kuranko.pe/wp-content/uploads/2026/09/WhatsApp-Image-2026-09-19-at-2.34.33-PM.jpeg, https://kuranko.pe/wp-content/uploads/2026/09/WhatsApp-Image-2026-09-19-at-2.34.31-PM.jpeg
A5: 17971 | B5: simple | C5: MKPF02ADA01KU0001 | E5: Kuranko - Adaptador - Post Mount +20mm (1 unid) - MKP - Usando, en buen estado | F5: 1 | G5: 0 | H5: visible | J5: <p>Adaptador Post Mount +20 mm fabricado en aluminio, diseñado para aumentar el diámetro del rotor en sistemas de freno compatibles.</p> | M5: taxable | O5: 1 | P5: 1 | S5: 0 | AA5: 25 | AB5: Ciclismo > Frenos > Adaptadores para frenos
A6: 17984 | B6: simple | C6: MKP77651165X | E6: Mavic - Kit - de Rueda - 1 Válvula, 2 Radios en J y 2 Nipples MKP | F6: 1 | G6: 0 | H6: visible | J6: <p>Kit de repuesto Mavic para mantenimiento y reparación de ruedas. Incluye los componentes necesarios para sustituir elementos de la rueda y realizar trabajos de mantenimiento.</p><p><strong>Contenido del kit:</strong></p><ul><li><p>1 válvula</p></li><li><p>2 radios en J</p></li><li><p>2 nipples</p></li></ul> | M6: taxable | O6: 1 | P6: 2 | S6: 0 | AA6: 45 | AB6: Ciclismo > Ruedas > Repuestos | AE6: https://kuranko.pe/wp-content/uploads/2026/09/WhatsApp-Image-2026-09-19-at-2.34.30-PM.jpeg, https://kuranko.pe/wp-content/uploads/2026/09/WhatsApp-Image-2026-09-19-at-2.34.29-PM.jpeg, https://kuranko.pe/wp-content/uploads/2026/09/WhatsApp-Image-2026-09-19-at-2.32.02-PM.jpeg
A7: 17985 | B7: simple | C7: MKPTB00211100 | E7: Maxxis - Llanta - Rekon Race 29 x 2.40 EXO/TR 120 TPI, - TB00211100 - MKP - Desmontado, nunca usado | F7: 1 | G7: 0 | H7: visible | J7: <p>Neumático <strong>Maxxis Rekon Race</strong> de <strong>29 x 2.40</strong>, desarrollado para <strong>XC y competición</strong>, con un diseño de banda de rodadura de bajo perfil que favorece una rodadura rápida en terrenos secos y circuitos de short track.</p><p>Esta versión incorpora carcasa <strong>120 TPI</strong>, protección lateral <strong>EXO</strong>, tecnología <strong>Tubeless Ready</strong> y aro plegable. La medida <strong>29 x 2.40 WT</strong> está optimizada para aros con un ancho interno de <strong>30 mm</strong>.</p><p><strong>Especificaciones:</strong></p><ul><li><p>Marca: <strong>Maxxis</strong></p></li><li><p>Modelo: <strong>Rekon Race</strong></p></li><li><p>Medida: <strong>29 x 2.40 WT</strong></p></li><li><p>ETRTO: <strong>61-622</strong></p></li><li><p>TPI: <strong>120</strong></p></li><li><p>Compuesto: <strong>Dual</strong></p></li><li><p>Carcasa: <strong>EXO</strong></p></li><li><p>Tecnología: <strong>Tubeless Ready (TR)</strong></p></li><li><p>Aro: <strong>Plegable</strong></p></li><li><p>Peso de catálogo: <strong>aprox. 814–816 g</strong></p></li><li><p>Uso recomendado: <strong>XC / XC Race</strong></p></li><li><p>Referencia: <strong>TB00211100</strong></p></li><li><p>Presentación: <strong>1 unidad</strong></p></li></ul> | M7: taxable | O7: 1 | P7: 1 | S7: 0 | AA7: 150 | AB7: Ciclismo > Ruedas > Cubiertas | AE7: https://kuranko.pe/wp-content/uploads/2026/09/WhatsApp-Image-2026-09-19-at-2.34.53-PM-3.jpeg, https://kuranko.pe/wp-content/uploads/2026/09/WhatsApp-Image-2026-09-19-at-2.34.53-PM-2.jpeg, https://kuranko.pe/wp-content/uploads/2026/09/WhatsApp-Image-2026-09-19-at-2.34.53-PM-1.jpeg
A8: 17996 | B8: simple | C8: DY37020.06015MKP | E8: ONOFF - Manillar - S6 Carbon 0.2, carbono, 31.8mm, 760mm ancho, 5mm rise, negro - MKP - Desmontado, nunca usado | F8: 1 | G8: 0 | H8: visible | J8: <p>Manillar de carbono diseñado para XC, down country y trail ligero, ofreciendo una excelente combinación entre bajo peso, rigidez y absorción de vibraciones. Fabricado en fibra de carbono unidireccional, proporciona una conducción precisa y un mayor confort, reduciendo la fatiga en rutas largas y terrenos técnicos.</p><p>Su diámetro de abrazadera de 31.8 mm garantiza compatibilidad con la mayoría de potencias del mercado, mientras que sus 760 mm de ancho y 5 mm de elevación ofrecen un equilibrio ideal entre control, estabilidad y eficiencia de pedaleo. El backsweep de 9° favorece una posición natural de las manos para una mayor comodidad.</p><p>Esta unidad corresponde a una pieza desmontada de bicicleta nueva, nunca utilizada, por lo que se encuentra en excelente estado estético y funcional.</p><p><strong>🛠️ Especificaciones:</strong></p><ul><li><p>Material: Fibra de carbono unidireccional</p></li><li><p>Diámetro de abrazadera: 31.8 mm</p></li><li><p>Ancho: 760 mm</p></li><li><p>Elevación (Rise): 5 mm</p></li><li><p>Backsweep: 9°</p></li><li><p>Upsweep: 0°</p></li><li><p>Color: Negro</p></li><li><p>Uso recomendado: XC / Down Country / Trail ligero</p></li><li><p>Estado: Desmontado, nunca usado</p></li></ul> | M8: taxable | O8: 1 | P8: 1 | S8: 0 | AA8: 680 | AB8: Ciclismo > Dirección > Manillares | AE8: https://kuranko.pe/wp-content/uploads/2026/09/WhatsApp-Image-2026-09-19-at-2.34.52-PM-1.jpeg, https://kuranko.pe/wp-content/uploads/2026/09/WhatsApp-Image-2026-09-19-at-2.34.52-PM-2.jpeg, https://kuranko.pe/wp-content/uploads/2026/09/WhatsApp-Image-2026-09-19-at-2.34.51-PM.jpeg, https://kuranko.pe/wp-content/uploads/2026/09/WhatsApp-Image-2026-09-19-at-2.34.50-PM-1.jpeg, https://kuranko.pe/wp-content/uploads/2026/09/WhatsApp-Image-2026-09-19-at-2.34.50-PM.jpeg, https://kuranko.pe/wp-content/uploads/2026/09/WhatsApp-Image-2026-09-19-at-2.34.49-PM-1.jpeg
A9: 18009 | B9: simple | C9: MKP00.4020.572.005 | E9: RockShox - Vástago - de aire - DebonAir C1 130 mm para Lyrik/Yari A1+ (2016+) - MKP - Usado, en buen estado | F9: 1 | G9: 0 | H9: visible | J9: <p>Vástago de aire DebonAir C1 de 130 mm para horquillas RockShox Lyrik y Yari compatibles. Permite configurar la horquilla para un recorrido de 130 mm mediante el sistema de aire DebonAir C1.</p><p><strong>Compatibilidad:</strong></p><ul><li><p>RockShox Lyrik A1-C3, 2016-2022</p></li><li><p>RockShox Yari A1-B3, 2016-2022</p></li></ul><p><strong>Especificaciones:</strong></p><ul><li><p>Sistema: DebonAir C1</p></li><li><p>Recorrido: 130 mm</p></li><li><p>Tipo: Vástago de aire / Air Shaft</p></li></ul> | M9: taxable | O9: 1 | P9: 1 | S9: 0 | AA9: 200 | AB9: Ciclismo > Amortiguador > Muelles para horquillas | AE9: https://kuranko.pe/wp-content/uploads/2026/09/WhatsApp-Image-2026-09-19-at-2.31.29-PM.jpeg, https://kuranko.pe/wp-content/uploads/2026/09/WhatsApp-Image-2026-09-19-at-2.31.28-PM.jpeg
A10: 18023 | B10: simple | C10: PRD-000009 | E10: Shimano - Descarrilador - SLX M7100 Shadow+ SGS Black 12s / Max 51t - MKP - Usado | F10: 1 | G10: 0 | H10: visible | J10: <p></p> | M10: taxable | O10: 1 | P10: 1 | S10: 0 | AA10: 250 | AB10: Ciclismo > Transmisión > Descarrilador | AE10: https://kuranko.pe/wp-content/uploads/2026/07/WhatsApp-Image-2026-07-24-at-7.19.49-PM.jpeg, https://kuranko.pe/wp-content/uploads/2026/07/WhatsApp-Image-2026-07-24-at-7.19.48-PM-1.jpeg
A11: 18024 | B11: simple | C11: MKP4550170451967 | E11: Shimano - Disco - SLX SM-RT64 Center Lock 180mm - MKP - Usado, en buen estado | F11: 1 | G11: 0 | H11: visible | J11: <p>Disco Shimano SLX SM-RT64 Center LockLa superficie de frenada en acero inoxidable cortada con precisión garantiza la limpieza de la pastilla en condiciones de barro y ayuda al enfriamiento bajo esfuerzos elevados.<br>Se incrementa la durabilidad y las prestaciones de la pastilla de freno<br>La araña en aleación de aluminio hace de soporte a la superficie del rotor, aumentando la rigidez y reduciendo el peso.Peso: alrededor de 153 g. (160 mm)<br>12 g más ligero que el SM-RT62.</p> | M11: taxable | O11: 1 | P11: 1 | S11: 0 | AB11: Ciclismo > Frenos > Discos para frenos | AE11: https://kuranko.pe/wp-content/uploads/2026/09/WhatsApp-Image-2026-09-19-at-2.31.54-PM.jpeg, https://kuranko.pe/wp-content/uploads/2026/09/WhatsApp-Image-2026-09-19-at-2.31.49-PM.jpeg, https://kuranko.pe/wp-content/uploads/2026/09/WhatsApp-Image-2026-09-19-at-2.31.47-PM.jpeg, https://kuranko.pe/wp-content/uploads/2026/09/WhatsApp-Image-2026-09-19-at-2.31.45-PM.jpeg, https://kuranko.pe/wp-content/uploads/2026/09/WhatsApp-Image-2026-09-19-at-2.31.43-PM.jpeg
A12: 18025 | B12: simple | C12: MKP0000000036 | E12: Shimano - Freno - delantero Deore XT M8100, sin pastillas - MKP - Usado, en buen estado | F12: 1 | G12: 0 | H12: visible | J12: Freno hidráulico de alto rendimiento diseñado para MTB XC, trail y enduro ligero, ofreciendo excelente potencia, modulación y control en todo tipo de terrenos. La serie Deore XT M8100 destaca por su tacto preciso y respuesta consistente, ideal para ciclistas que buscan rendimiento confiable tanto en rutas técnicas como en largas jornadas de montaña. La construcción ligera y resistente mejora la disipación de calor y mantiene un funcionamiento estable incluso en descensos exigentes. Esta unidad corresponde a una pieza MKP desmontada, usada y en buen estado funcional y estético. Se entrega sin pastillas de freno. 🛠️ Especificaciones: Posición: Delantero Serie: Shimano Deore XT M8100 Tipo: Freno hidráulico de disco Color: Negro Incluye maneta y caliper No incluye pastillas Estado: MKP – usado, en buen estado | M12: taxable | O12: 1 | P12: 1 | S12: 0 | Z12: 300 | AA12: 300 | AB12: Ciclismo > Frenos > Frenos de disco y aro | AE12: https://kuranko.pe/wp-content/uploads/2026/07/WhatsApp-Image-2026-07-22-at-4.51.42-PM.jpeg, https://kuranko.pe/wp-content/uploads/2026/07/WhatsApp-Image-2026-07-22-at-4.51.41-PM-1.jpeg, https://kuranko.pe/wp-content/uploads/2026/07/WhatsApp-Image-2026-07-22-at-4.51.41-PM.jpeg, https://kuranko.pe/wp-content/uploads/2026/07/WhatsApp-Image-2026-07-22-at-4.51.40-PM-2.jpeg, https://kuranko.pe/wp-content/uploads/2026/07/WhatsApp-Image-2026-07-22-at-4.51.40-PM-1.jpeg, https://kuranko.pe/wp-content/uploads/2026/07/WhatsApp-Image-2026-07-22-at-4.51.40-PM.jpeg, https://kuranko.pe/wp-content/uploads/2026/07/WhatsApp-Image-2026-07-22-at-4.51.39-PM-1.jpeg
A13: 18026 | B13: simple | C13: MKP0000000051 | E13: Shimano - Frenos - Deore xt 4 pistones usados MKP | F13: 1 | G13: 0 | H13: visible | M13: taxable | O13: 1 | P13: 0 | S13: 0 | AB13: Ciclismo > Frenos > Frenos de disco y aro
A14: 18027 | B14: simple | C14: MKP0000000040 | E14: Shimano - Piñon - SLX CS-M7100 Micro Spline 12V - MKP - Usado, en buen estado | F14: 1 | G14: 0 | H14: visible | J14: Cassette diseñado para transmisiones Shimano 12 velocidades, ofreciendo cambios suaves, rápidos y precisos gracias a la tecnología Hyperglide+. La serie SLX M7100 proporciona excelente rendimiento en XC, trail y enduro, manteniendo una buena relación entre durabilidad, peso y eficiencia de pedaleo. Su construcción optimizada mejora la retención de cadena y permite cambios más fluidos incluso bajo carga en terrenos técnicos y subidas exigentes. Compatible con núcleos Micro Spline de Shimano para transmisiones MTB modernas. Esta unidad corresponde a una pieza MKP desmontada, usada y en buen estado funcional y estético. 🛠️ Especificaciones: Serie: Shimano SLX CS-M7100 Velocidades: 12V Sistema: Hyperglide+ Núcleo compatible: Micro Spline Uso recomendado: MTB / XC / Trail / Enduro Color: Plata / Negro Estado: MKP – usado, en buen estado | M14: taxable | O14: 1 | P14: 1 | S14: 0 | Z14: 280 | AA14: 280 | AB14: Ciclismo > Transmisión > Piñones | AE14: https://kuranko.pe/wp-content/uploads/2026/07/WhatsApp-Image-2026-07-24-at-7.18.20-PM-3.jpeg, https://kuranko.pe/wp-content/uploads/2026/07/WhatsApp-Image-2026-07-24-at-7.18.21-PM.jpeg
A15: 18028 | B15: simple | C15: MKP0000000017 | E15: Shimano - Piñon - XT CS-M8100 Micro Spline 12V - MKP - Usado, en buen estado | F15: 1 | G15: 0 | H15: visible | J15: Para adaptar el amado XT al nuevo estándar de 12 velocidades y ofrecer el máximo rendimiento, Shimano presenta el piñón de cassette CS-M8100. Incorpora la tecnología del cuerpo de cassette Micro Spline del conocido XTR 12V y el perfil de los dientes Hyperglide+, lo que hace que el cambio sea aún más silencioso y eficiente. Características Los nuevos diseños de rampa de cambio brindan los cambios más rápidos y suaves con Hyperglide+ Construcción más ligera y más rígida. Reduce la inercia del cassette, lo que origina una aceleración más rápida e incrementa la seguridad de la cadena. El piñón inferior 10D realizado con la nueva construcción Freehub. Compatibilidad: 12 velocidades. No compatible con cuerpo de cassette Shimano Standard. Diez primeros piñones en acero, últimos dos en aluminio anodizado negro. Combinaciones disponibles: 10-45D, 10-51D. Dientes: 10-51D: 10-12-14-16-18-21-24-28-33-39-45-51 (471 g) | M15: taxable | O15: 1 | P15: 1 | S15: 0 | Z15: 360 | AA15: 400 | AB15: Ciclismo > Transmisión > Piñones | AE15: https://kuranko.pe/wp-content/uploads/2026/07/WhatsApp-Image-2026-07-22-at-4.51.52-PM-2.jpeg, https://kuranko.pe/wp-content/uploads/2026/07/WhatsApp-Image-2026-07-22-at-4.51.52-PM-1.jpeg, https://kuranko.pe/wp-content/uploads/2026/07/WhatsApp-Image-2026-07-22-at-4.51.52-PM.jpeg, https://kuranko.pe/wp-content/uploads/2026/07/WhatsApp-Image-2026-07-22-at-4.51.51-PM-2.jpeg, https://kuranko.pe/wp-content/uploads/2026/07/WhatsApp-Image-2026-07-22-at-4.51.51-PM-1.jpeg
A16: 18029 | B16: simple | C16: MKP0000000020 | E16: Shimano - shifter - SLX M7100 1x12v - MKP - Usado, en buen estado | F16: 1 | G16: 0 | H16: visible | J16: Maneta de cambios diseñada para transmisiones Shimano 12 velocidades, ofreciendo cambios rápidos, precisos y suaves incluso en terrenos exigentes. El SLX M7100 incorpora tecnología Rapidfire Plus con sistema 2-Way Release, permitiendo accionar los cambios con pulgar o índice para una respuesta más natural y eficiente en trail, enduro y XC. Su diseño ergonómico mejora la sensación de control en el cockpit, mientras que el mecanismo Instant Release proporciona cambios más rápidos bajo carga. Compatible con transmisiones Shimano Hyperglide+ de 12 velocidades. 🛠️ Especificaciones: Velocidades: 1x12v Serie: Shimano SLX M7100 Tecnología: Rapidfire Plus Función: 2-Way Release Montaje: Abrazadera Compatibilidad: Shimano 12 velocidades Hyperglide+ Color: Negro | M16: taxable | O16: 1 | P16: 1 | S16: 0 | Z16: 110 | AA16: 200 | AB16: Ciclismo > Transmisión > Shifter
A17: 18030 | B17: simple | C17: MKP0000000021 | E17: Shimano PRO - Manillar - Tharsis 35 Carbon 10 Rise, 780mm, negro - MKP - Usado, en buen estado | F17: 1 | G17: 0 | H17: visible | J17: Diseñado para brindarle una mejor experiencia en bicicleta deportiva, el manillar PRO Tharsis 3Five Carbon Mini Rise está fabricado con fibra de carbono que combina ahorro de peso, cumplimiento y rigidez de la dirección para carreras de cross country o trail. Tienen una elevación de 10 milímetros, un retroceso de 9 grados, un retroceso de 4 grados y miden 780 milímetros de ancho. Como todos los manillares Tharsis 3Five, también cuentan con un diámetro de sujeción sobredimensionado de 35 milímetros. Especificaciones Uso: All Mountain, Cross Country, Enduro Diámetro de la abrazadera: 35 mm Ancho del manillar: 780 mm Rise: 10 mm Backsweep: 9° Upsweep: 4° Material: Carbono Peso: 195g | M17: taxable | O17: 1 | P17: 1 | S17: 0 | Z17: 450 | AA17: 450 | AB17: Ciclismo > Dirección > Manillares | AE17: https://kuranko.pe/wp-content/uploads/2026/07/WhatsApp-Image-2026-07-24-at-7.19.45-PM-1.jpeg, https://kuranko.pe/wp-content/uploads/2026/07/WhatsApp-Image-2026-07-24-at-7.19.45-PM.jpeg, https://kuranko.pe/wp-content/uploads/2026/07/WhatsApp-Image-2026-07-24-at-7.19.44-PM-1.jpeg, https://kuranko.pe/wp-content/uploads/2026/07/WhatsApp-Image-2026-07-24-at-7.19.44-PM.jpeg, https://kuranko.pe/wp-content/uploads/2026/07/WhatsApp-Image-2026-07-24-at-7.19.43-PM-2.jpeg
A18: 18031 | B18: simple | C18: MKP0000000027 | E18: Sin marca - cámara - MTB 29 Universal MKP | F18: 1 | G18: 0 | H18: visible | J18: Cámara diseñada para bicicletas de montaña aro 29, ideal para uso recreativo, XC, trail y enduro. Fabricada en caucho resistente para ofrecer buena retención de aire y durabilidad en diferentes condiciones de terreno. Compatible con una amplia variedad de neumáticos MTB aro 29 y disponible para válvula Presta o Schrader según la configuración de la bicicleta. Su construcción flexible facilita la instalación y el transporte como repuesto durante rutas y competencias. 🛠️ Especificaciones: Medida: Aro 29 Uso: MTB / XC / Trail / Enduro Material: Caucho / butilo Compatible con neumáticos MTB 29” Fácil instalación Buena resistencia a pinchazos y deformaciones | M18: taxable | O18: 1 | P18: 2 | S18: 0 | Z18: 20 | AA18: 20 | AB18: Ciclismo > Ruedas > Cámaras
A19: 18034 | B19: simple | C19: MKP0000000023 | E19: Specialized - Portabotella - Zee Cage integrada - MKP - Usado, en buen estado | F19: 1 | G19: 0 | H19: visible | J19: Portabidón diseñado para MTB y gravel que combina un diseño compacto con una multiherramienta integrada EMT, ideal para realizar ajustes rápidos durante la ruta. Su sistema de carga lateral facilita extraer e insertar el bidón en cuadros con espacio reducido, especialmente en bicicletas de suspensión completa o cuadros pequeños. Fabricado en material compuesto reforzado, ofrece excelente resistencia y durabilidad manteniendo un peso contenido. El diseño minimalista y deportivo se integra perfectamente con bicicletas modernas de trail, enduro y XC. Diseño de carga lateral Carga derecha para tubo inferior y carga izquierda para tubo de sillín Construcción en composite reforzado Diseño compacto y minimalista Gráficos modernos estilo Specialized | M19: taxable | O19: 1 | P19: 1 | S19: 0 | Z19: 40 | AA19: 40 | AB19: Ciclismo > Accesorios > Bidones & portabidones | AE19: https://kuranko.pe/wp-content/uploads/2026/07/WhatsApp-Image-2026-07-22-at-4.51.33-PM-1.jpeg, https://kuranko.pe/wp-content/uploads/2026/07/WhatsApp-Image-2026-07-22-at-4.51.33-PM.jpeg, https://kuranko.pe/wp-content/uploads/2026/07/WhatsApp-Image-2026-07-22-at-4.51.32-PM-3.jpeg, https://kuranko.pe/wp-content/uploads/2026/07/WhatsApp-Image-2026-07-22-at-4.51.32-PM-2.jpeg
